<?xml version="1.0" encoding="utf-8"?>
<!-- This URDF was automatically created by SolidWorks to URDF Exporter! Originally created by Stephen Brawner (brawner@gmail.com) 
     Commit Version: 1.6.0-1-g15f4949  Build Version: 1.6.7594.29634
     For more information, please see http://wiki.ros.org/sw_urdf_exporter -->
<robot
  name="elec_robot">
  <link
    name="base_link">
    <inertial>
      <origin
        xyz="-0.063390678355428 -0.00017399731701595 -0.0627037879155704"
        rpy="0 0 0" />
      <mass
        value="4.21318595552561" />
      <inertia
        ixx="0.00676660552182087"
        ixy="2.95610259360452E-06"
        ixz="-0.000265609386682897"
        iyy="0.003470615075681"
        iyz="-1.08325224631569E-06"
        izz="0.00606201411762415" />
    </inertial>
    <visual>
      <origin
        xyz="0 0 0"
        rpy="0 0 0" />
      <geometry>
        <mesh
          filename="../meshes/base_link.STL" />
      </geometry>
      <material
        name="">
        <color
          rgba="0.498039215686275 0.498039215686275 0.498039215686275 1" />
      </material>
    </visual>
    <collision>
      <origin
        xyz="0 0 0.3"
        rpy="0 0 0" />
      <geometry>
          <box size="0.3 0.3 0.4" />
      </geometry>
    </collision>
  </link>
  <link
    name="r_hip_roll">
    <inertial>
      <origin
        xyz="-0.000484394388589273 -0.0035644199825704 0.0624748745130607"
        rpy="0 0 0" />
      <mass
        value="1.26570645289757" />
      <inertia
        ixx="0.000911357279657079"
        ixy="-5.84583950853321E-07"
        ixz="3.27087750711814E-06"
        iyy="0.00161880741132025"
        iyz="5.48842422146512E-05"
        izz="0.000837158301546913" />
    </inertial>
    <visual>
      <origin
        xyz="0 0 0"
        rpy="0 0 0" />
      <geometry>
        <mesh
          filename="../meshes/right_leg_link1.STL" />
      </geometry>
      <material
        name="">
        <color
          rgba="0.498039215686275 0.498039215686275 0.498039215686275 1" />
      </material>
    </visual>
    <collision>
      <origin
        xyz="0 0 0"
        rpy="0 0 0" />
      <geometry>
        <mesh
          filename="../meshes/right_leg_link1.STL" />
      </geometry>
    </collision>
  </link>
  <joint
    name="r_hip_roll"
    type="revolute">
    <origin
      xyz="-0.06635 -0.12 -0.0685"
      rpy="1.5708 0 1.5743" />
    <parent
      link="base_link" />
    <child
      link="r_hip_roll" />
    <axis
      xyz="-0.0035389 0 0.99999" />
    <limit
      lower="-0.349"
      upper="0.349"
      effort="216"
      velocity="15.132" />
  </joint>
  <link
    name="r_hip_yaw">
    <inertial>
      <origin
        xyz="-0.00760028540236322 -0.0822957836688344 0.000117110159231881"
        rpy="0 0 0" />
      <mass
        value="2.33471632301263" />
      <inertia
        ixx="0.00485178292308853"
        ixy="-2.74701622336868E-06"
        ixz="2.94569221015733E-06"
        iyy="0.00264126642378477"
        iyz="1.10236426957144E-05"
        izz="0.00249365984837431" />
    </inertial>
    <visual>
      <origin
        xyz="0 0 0"
        rpy="0 0 0" />
      <geometry>
        <mesh
          filename="../meshes/right_leg_link2.STL" />
      </geometry>
      <material
        name="">
        <color
          rgba="0.647058823529412 0.619607843137255 0.588235294117647 1" />
      </material>
    </visual>
    <collision>
      <origin
        xyz="0 0 0"
        rpy="0 0 0" />
      <geometry>
        <mesh
          filename="../meshes/right_leg_link2.STL" />
      </geometry>
    </collision>
  </link>
  <joint
    name="r_hip_yaw"
    type="revolute">
    <origin
      xyz="-0.0002348 -0.036 0.06635"
      rpy="0 0 0" />
    <parent
      link="r_hip_roll" />
    <child
      link="r_hip_yaw" />
    <axis
      xyz="0 1 0" />
    <limit
      lower="-0.785"
      upper="0.785"
      effort="192"
      velocity="17.02" />
  </joint>
  <link
    name="r_upper_leg">
    <inertial>
      <origin
        xyz="0.0593015162552617 -0.152301200282686 0.0193017303365229"
        rpy="0 0 0" />
      <mass
        value="4.11343393723113" />
      <inertia
        ixx="0.00836480619029492"
        ixy="-1.34052074501402E-05"
        ixz="-6.87348345329721E-06"
        iyy="0.00408711520333663"
        iyz="9.25299663821187E-05"
        izz="0.00516446790436521" />
    </inertial>
    <visual>
      <origin
        xyz="0 0 0"
        rpy="0 0 0" />
      <geometry>
        <mesh
          filename="../meshes/right_leg_link3.STL" />
      </geometry>
      <material
        name="">
        <color
          rgba="0.776470588235294 0.756862745098039 0.737254901960784 1" />
      </material>
    </visual>
    <collision>
      <origin
        xyz="0 0 0"
        rpy="0 0 0" />
      <geometry>
        <mesh
          filename="../meshes/right_leg_link3.STL" />
      </geometry>
    </collision>
  </link>
  <joint
    name="r_hip_pitch"
    type="revolute">
    <origin
      xyz="-0.055 -0.09 -5.3533E-05"
      rpy="0 0 0" />
    <parent
      link="r_hip_yaw" />
    <child
      link="r_upper_leg" />
    <axis
      xyz="-1 0 -0.00097332" />
    <limit
      lower="-0.61"
      upper="1.466"
      effort="352"
      velocity="14.39" />
  </joint>
  <link
    name="r_lower_leg">
    <inertial>
      <origin
        xyz="0.0240215521121228 -0.168858978918757 -0.0187732319594902"
        rpy="0 0 0" />
      <mass
        value="1.78257240638262" />
      <inertia
        ixx="0.00852957510775007"
        ixy="4.84388336902694E-05"
        ixz="7.49694608509064E-06"
        iyy="0.00137473840306633"
        iyz="-0.000787972654152031"
        izz="0.00776444265047781" />
    </inertial>
    <visual>
      <origin
        xyz="0 0 0"
        rpy="0 0 0" />
      <geometry>
        <mesh
          filename="../meshes/right_leg_link4.STL" />
      </geometry>
      <material
        name="">
        <color
          rgba="0.776470588235294 0.756862745098039 0.737254901960784 1" />
      </material>
    </visual>
    <collision>
      <origin
        xyz="0 0 0"
        rpy="0 0 0" />
      <geometry>
        <mesh
          filename="../meshes/right_leg_link4.STL" />
      </geometry>
    </collision>
  </link>
  <joint
    name="r_knee"
    type="revolute">
    <origin
      xyz="0.02996 -0.33756 0.040662"
      rpy="0 0 0" />
    <parent
      link="r_upper_leg" />
    <child
      link="r_lower_leg" />
    <axis
      xyz="1 0 0.00097332" />
    <limit
      lower="0"
      upper="1.99"
      effort="770"
      velocity="6.54" />
  </joint>
  <link
    name="r_ankle">
    <inertial>
      <origin
        xyz="0.0134998873467807 -3.99185135613322E-07 1.40020056360046E-05"
        rpy="0 0 0" />
      <mass
        value="0.0978842172681051" />
      <inertia
        ixx="6.73461239849819E-06"
        ixy="-4.82455410424562E-10"
        ixz="-1.16021363212383E-09"
        iyy="8.9219489602129E-06"
        iyz="9.24850672156848E-10"
        izz="6.73437513649448E-06" />
    </inertial>
    <visual>
      <origin
        xyz="0 0 0"
        rpy="0 0 0" />
      <geometry>
        <mesh
          filename="../meshes/right_leg_link5.STL" />
      </geometry>
      <material
        name="">
        <color
          rgba="0.686274509803922 0.658823529411765 0.63921568627451 1" />
      </material>
    </visual>
    <collision>
      <origin
        xyz="0 0 0"
        rpy="0 0 0" />
      <geometry>
        <mesh
          filename="../meshes/right_leg_link5.STL" />
      </geometry>
    </collision>
  </link>
  <joint
    name="r_ankle_pitch"
    type="revolute">
    <origin
      xyz="0.010535 -0.33804 -0.036439"
      rpy="0 0 0" />
    <parent
      link="r_lower_leg" />
    <child
      link="r_ankle" />
    <axis
      xyz="-1 0 -0.00097332" />
    <limit
      lower="-0.43"
      upper="0.7"
      effort="48"
      velocity="32.46" />
  </joint>
  <link
    name="r_foot">
    <inertial>
      <origin
        xyz="2.87637938942136E-05 -0.0423042312642217 0.00683814187080156"
        rpy="0 0 0" />
      <mass
        value="0.696870967743547" />
      <inertia
        ixx="0.00159827017411562"
        ixy="-1.71239450478004E-07"
        ixz="1.05323347110978E-06"
        iyy="0.001963204734971"
        iyz="2.21709456494896E-05"
        izz="0.000447610769336173" />
    </inertial>
    <visual>
      <origin
        xyz="0 0 0"
        rpy="0 0 0" />
      <geometry>
        <mesh
          filename="../meshes/right_leg_link6.STL" />
      </geometry>
      <material
        name="">
        <color
          rgba="0.776470588235294 0.756862745098039 0.737254901960784 1" />
      </material>
    </visual>
    <collision>
      <origin
        xyz="0 0 0"
        rpy="0 0 0" />
      <geometry>
        <mesh
          filename="../meshes/right_leg_link6.STL" />
      </geometry>
    </collision>
  </link>
  <joint
    name="r_ankle_roll"
    type="revolute">
    <origin
      xyz="0.013486853748963 0 0.0135131333714657"
      rpy="0 0 0" />
    <parent
      link="r_ankle" />
    <child
      link="r_foot" />
    <axis
      xyz="-0.000973322694288324 -0.000115690766440228 0.999999519629174" />
    <limit
      lower="-0.23"
      upper="0.23"
      effort="7.1"
      velocity="210" />
  </joint>
  <link
    name="l_hip_roll">
    <inertial>
      <origin
        xyz="0.000101479177773089 -0.00356442012352599 0.0625112465725188"
        rpy="0 0 0" />
      <mass
        value="1.26570642683626" />
      <inertia
        ixx="0.00090805559065837"
        ixy="-4.94092937467766E-08"
        ixz="-8.41697735735063E-07"
        iyy="0.00161880981973977"
        iyz="5.47438078659238E-05"
        izz="0.000840462408426574" />
    </inertial>
    <visual>
      <origin
        xyz="0 0 0"
        rpy="0 0 0" />
      <geometry>
        <mesh
          filename="../meshes/left_leg_link1.STL" />
      </geometry>
      <material
        name="">
        <color
          rgba="0.498039215686275 0.498039215686275 0.498039215686275 1" />
      </material>
    </visual>
    <collision>
      <origin
        xyz="0 0 0"
        rpy="0 0 0" />
      <geometry>
        <mesh
          filename="../meshes/left_leg_link1.STL" />
      </geometry>
    </collision>
  </link>
  <joint
    name="l_hip_roll"
    type="revolute">
    <origin
      xyz="-0.0663499999972001 0.120000000001548 -0.0685000000000029"
      rpy="1.57079632568888 0 1.57433520239569" />
    <parent
      link="base_link" />
    <child
      link="l_hip_roll" />
    <axis
      xyz="-0.00353886823751741 0 0.999993738186194" />
    <limit
      lower="-0.349"
      upper="0.349"
      effort="216"
      velocity="15.132" />
  </joint>
  <link
    name="l_hip_yaw">
    <inertial>
      <origin
        xyz="0.00706651342587888 -0.0835785861012155 -0.000128071095579496"
        rpy="0 0 0" />
      <mass
        value="2.33090977511357" />
      <inertia
        ixx="0.00484834176085321"
        ixy="2.68250720211032E-06"
        ixz="-2.40123952417819E-05"
        iyy="0.00262597471386437"
        iyz="-5.10536198639952E-06"
        izz="0.00248772485025142" />
    </inertial>
    <visual>
      <origin
        xyz="0 0 0"
        rpy="0 0 0" />
      <geometry>
        <mesh
          filename="../meshes/left_leg_link2.STL" />
      </geometry>
      <material
        name="">
        <color
          rgba="0.498039215686275 0.498039215686275 0.498039215686275 1" />
      </material>
    </visual>
    <collision>
      <origin
        xyz="0 0 0"
        rpy="0 0 0" />
      <geometry>
        <mesh
          filename="../meshes/left_leg_link2.STL" />
      </geometry>
    </collision>
  </link>
  <joint
    name="l_hip_yaw"
    type="revolute">
    <origin
      xyz="-0.000234803907688874 -0.0360000000733847 0.0663495844887467"
      rpy="0 0 0" />
    <parent
      link="l_hip_roll" />
    <child
      link="l_hip_yaw" />
    <axis
      xyz="0 1 0" />
    <limit
      lower="-0.785"
      upper="0.785"
      effort="192"
      velocity="17.02" />
  </joint>
  <link
    name="l_upper_leg">
    <inertial>
      <origin
        xyz="-0.058822252864083 -0.151126880184462 0.0200422512669933"
        rpy="0 0 0" />
      <mass
        value="4.09720559034099" />
      <inertia
        ixx="0.00836698414161195"
        ixy="1.4128558019376E-05"
        ixz="-2.33395492957285E-05"
        iyy="0.00409840018291529"
        iyz="9.17434155180876E-05"
        izz="0.00516480878896616" />
    </inertial>
    <visual>
      <origin
        xyz="0 0 0"
        rpy="0 0 0" />
      <geometry>
        <mesh
          filename="../meshes/left_leg_link3.STL" />
      </geometry>
      <material
        name="">
        <color
          rgba="0.647058823529412 0.619607843137255 0.588235294117647 1" />
      </material>
    </visual>
    <collision>
      <origin
        xyz="0 0 0"
        rpy="0 0 0" />
      <geometry>
        <mesh
          filename="../meshes/left_leg_link3.STL" />
      </geometry>
    </collision>
  </link>
  <joint
    name="l_hip_pitch"
    type="revolute">
    <origin
      xyz="0.054997 -0.09 -0.00058083"
      rpy="0 0 0" />
    <parent
      link="l_hip_yaw" />
    <child
      link="l_upper_leg" />
    <axis
      xyz="0.99994 0 -0.010561" />
    <limit
      lower="-1.47"
      upper="0.61"
      effort="352"
      velocity="14.4" />
  </joint>
  <link
    name="l_lower_leg">
    <inertial>
      <origin
        xyz="0.0117715489098182 -0.168588264667065 -0.0213848885091233"
        rpy="0 0 0" />
      <mass
        value="1.7825715893692" />
      <inertia
        ixx="0.00852938436830504"
        ixy="-5.68699025206407E-05"
        ixz="-1.36276832443712E-05"
        iyy="0.00140051756052701"
        iyz="-0.000881363529599034"
        izz="0.00773884412788872" />
    </inertial>
    <visual>
      <origin
        xyz="0 0 0"
        rpy="0 0 0" />
      <geometry>
        <mesh
          filename="../meshes/left_leg_link4.STL" />
      </geometry>
      <material
        name="">
        <color
          rgba="0.776470588235294 0.756862745098039 0.737254901960784 1" />
      </material>
    </visual>
    <collision>
      <origin
        xyz="0 0 0"
        rpy="0 0 0" />
      <geometry>
        <mesh
          filename="../meshes/left_leg_link4.STL" />
      </geometry>
    </collision>
  </link>
  <joint
    name="l_knee"
    type="revolute">
    <origin
      xyz="-0.065566 -0.33755 0.041408"
      rpy="0 0 0" />
    <parent
      link="l_upper_leg" />
    <child
      link="l_lower_leg" />
    <axis
      xyz="-0.99994 0 0.010561" />
    <limit
      lower="-1.99"
      upper="0"
      effort="770"
      velocity="6.54" />
  </joint>
  <link
    name="l_ankle">
    <inertial>
      <origin
        xyz="-0.0134993419709958 -2.30035837822662E-07 0.000143466889776511"
        rpy="0 0 0" />
      <mass
        value="0.0978842041002577" />
      <inertia
        ixx="6.73458706741208E-06"
        ixy="-5.62916430407258E-10"
        ixz="-1.06252588736305E-09"
        iyy="8.92204721980441E-06"
        iyz="-2.87144161087154E-08"
        izz="6.73430099391579E-06" />
    </inertial>
    <visual>
      <origin
        xyz="0 0 0"
        rpy="0 0 0" />
      <geometry>
        <mesh
          filename="../meshes/left_leg_link5.STL" />
      </geometry>
      <material
        name="">
        <color
          rgba="0.686274509803922 0.658823529411765 0.63921568627451 1" />
      </material>
    </visual>
    <collision>
      <origin
        xyz="0 0 0"
        rpy="0 0 0" />
      <geometry>
        <mesh
          filename="../meshes/left_leg_link5.STL" />
      </geometry>
    </collision>
  </link>
  <joint
    name="l_ankle_pitch"
    type="revolute">
    <origin
      xyz="0.025061 -0.33747 -0.041657"
      rpy="0 0 0" />
    <parent
      link="l_lower_leg" />
    <child
      link="l_ankle" />
    <axis
      xyz="0.99994 0 -0.010561" />
    <limit
      lower="-0.7"
      upper="0.44"
      effort="48"
      velocity="32.46" />
  </joint>
  <link
    name="l_foot">
    <inertial>
      <origin
        xyz="0.000113621615493775 -0.0422078996808901 0.00740873079832144"
        rpy="0 0 0" />
      <mass
        value="0.696870972702741" />
      <inertia
        ixx="0.00159814142716954"
        ixy="-1.32860986264624E-07"
        ixz="-1.221900313224E-05"
        iyy="0.00196352716935352"
        iyz="1.67269540138722E-06"
        izz="0.000447417122670614" />
    </inertial>
    <visual>
      <origin
        xyz="0 0 0"
        rpy="0 0 0" />
      <geometry>
        <mesh
          filename="../meshes/left_leg_link6.STL" />
      </geometry>
      <material
        name="">
        <color
          rgba="0.776470588235294 0.756862745098039 0.737254901960784 1" />
      </material>
    </visual>
    <collision>
      <origin
        xyz="0 0 0"
        rpy="0 0 0" />
      <geometry>
        <mesh
          filename="../meshes/left_leg_link6.STL" />
      </geometry>
    </collision>
  </link>
  <joint
    name="l_ankle_roll"
    type="revolute">
    <origin
      xyz="-0.0133566928718022 0.000180983338823881 0.0136406011802786"
      rpy="0 0 0" />
    <parent
      link="l_ankle" />
    <child
      link="l_foot" />
    <axis
      xyz="0.0105595788994797 0.0134061732568388 0.999854374302615" />
    <limit
      lower="-0.23"
      upper="0.23"
      effort="7.1"
      velocity="210" />
  </joint>
  <link
    name="waist_link1">
    <inertial>
      <origin
        xyz="-0.0271621068243299 0.0611087330915202 -0.00010885334727595"
        rpy="0 0 0" />
      <mass
        value="2.60651993737473" />
      <inertia
        ixx="0.00317121331847164"
        ixy="2.77429886517203E-05"
        ixz="3.44014436742496E-06"
        iyy="0.00204675064607033"
        iyz="4.85790665994511E-07"
        izz="0.00211997108148766" />
    </inertial>
    <visual>
      <origin
        xyz="0 0 0"
        rpy="0 0 0" />
      <geometry>
        <mesh
          filename="../meshes/waist_link1.STL" />
      </geometry>
      <material
        name="">
        <color
          rgba="0.498039215686275 0.498039215686275 0.498039215686275 1" />
      </material>
    </visual>
    <collision>
      <origin
        xyz="0 0 0"
        rpy="0 0 0" />
      <geometry>
        <mesh
          filename="../meshes/waist_link1.STL" />
      </geometry>
    </collision>
  </link>
  <joint
    name="waist_yaw"
    type="revolute">
    <origin
      xyz="0 0 -0.0110000000000039"
      rpy="1.57079632568888 0 1.57433520239569" />
    <parent
      link="base_link" />
    <child
      link="waist_link1" />
    <axis
      xyz="0 -1 0" />
    <limit
      lower="-1.05"
      upper="1.05"
      effort="192"
      velocity="17.01" />
  </joint>
  <link
    name="body">
    <inertial>
      <origin
        xyz="0.0861722601311518 0.238376654954689 -0.00115476134131648"
        rpy="0 0 0" />
      <mass
        value="20.4808788913282" />
      <inertia
        ixx="0.0784955161034964"
        ixy="-0.0011296987688785"
        ixz="-0.000181612211060661"
        iyy="0.121854076033088"
        iyz="0.000111907170762519"
        izz="0.148143664438569" />
    </inertial>
    <visual>
      <origin
        xyz="0 0 0"
        rpy="0 0 0" />
      <geometry>
        <mesh
          filename="../meshes/body.STL" />
      </geometry>
      <material
        name="">
        <color
          rgba="0.686274509803922 0.658823529411765 0.63921568627451 1" />
      </material>
    </visual>
    <collision>
      <origin
        xyz="0 0 0"
        rpy="0 0 0" />
      <geometry>
        <mesh
          filename="../meshes/body.STL" />
      </geometry>
    </collision>
  </link>
  <joint
    name="waist_pitch"
    type="revolute">
    <origin
      xyz="-0.0849994677458334 0.0655000000003366 -0.000300803725762355"
      rpy="0 0 0" />
    <parent
      link="waist_link1" />
    <child
      link="body" />
    <axis
      xyz="-0.999993738186276 0 -0.00353886821419433" />
    <limit
      lower="-1.4"
      upper="1.22"
      effort="400"
      velocity="4.82" />
  </joint>
  <link
    name="right_arm_link1">
    <inertial>
      <origin
        xyz="-0.0694543010713518 1.56620283437436E-05 -0.0155098298553125"
        rpy="0 0 0" />
      <mass
        value="1.02141652432608" />
      <inertia
        ixx="0.000663170251737516"
        ixy="9.08633035254261E-07"
        ixz="1.24857180934496E-05"
        iyy="0.000670182456762617"
        iyz="-2.38161460681397E-06"
        izz="0.000749331719788452" />
    </inertial>
    <visual>
      <origin
        xyz="0 0 0"
        rpy="0 0 0" />
      <geometry>
        <mesh
          filename="../meshes/right_arm_link1.STL" />
      </geometry>
      <material
        name="">
        <color
          rgba="0.686274509803922 0.658823529411765 0.63921568627451 1" />
      </material>
    </visual>
    <collision>
      <origin
        xyz="0 0 0"
        rpy="0 0 0" />
      <geometry>
        <mesh
          filename="../meshes/right_arm_link1.STL" />
      </geometry>
    </collision>
  </link>
  <joint
    name="right_arm_pitch"
    type="revolute">
    <origin
      xyz="-0.0859994614840193 0.361000000000337 -0.000304342267143487"
      rpy="0 0 0" />
    <parent
      link="body" />
    <child
      link="right_arm_link1" />
    <axis
      xyz="-0.999993738186276 0 -0.00353886821419696" />
    <limit
      lower="-3.14"
      upper="3.14"
      effort="35"
      velocity="3.93" />
  </joint>
  <link
    name="right_arm_link2">
    <inertial>
      <origin
        xyz="-0.000549392298772988 -0.106080914404913 -0.0151458561464202"
        rpy="0 0 0" />
      <mass
        value="1.14381531774174" />
      <inertia
        ixx="0.000864202829982537"
        ixy="8.82468215444783E-07"
        ixz="1.03473651149251E-07"
        iyy="0.000870188545966125"
        iyz="-2.92915606125069E-05"
        izz="0.000875858293217756" />
    </inertial>
    <visual>
      <origin
        xyz="0 0 0"
        rpy="0 0 0" />
      <geometry>
        <mesh
          filename="../meshes/right_arm_link2.STL" />
      </geometry>
      <material
        name="">
        <color
          rgba="0.898039215686275 0.917647058823529 0.929411764705882 1" />
      </material>
    </visual>
    <collision>
      <origin
        xyz="0 0 0"
        rpy="0 0 0" />
      <geometry>
        <mesh
          filename="../meshes/right_arm_link2.STL" />
      </geometry>
    </collision>
  </link>
  <joint
    name="right_arm_roll"
    type="revolute">
    <origin
      xyz="-0.0760552614837839 -9.33372071758032E-05 0.0154806708210933"
      rpy="0 0 0" />
    <parent
      link="right_arm_link1" />
    <child
      link="right_arm_link2" />
    <axis
      xyz="0.00353880607200826 0.00592617190307141 -0.999976178385345" />
    <limit
      lower="-0.09"
      upper="3.49"
      effort="35"
      velocity="3.93" />
  </joint>
  <link
    name="right_arm_link3">
    <inertial>
      <origin
        xyz="0.0141038773924585 -0.0902942065905267 -0.00110305469706767"
        rpy="0 0 0" />
      <mass
        value="1.06927815633633" />
      <inertia
        ixx="0.000861344249910917"
        ixy="-2.43457135391299E-05"
        ixz="-4.94727242406066E-06"
        iyy="0.000727263811933715"
        iyz="-9.28660208437265E-08"
        izz="0.000789560853389174" />
    </inertial>
    <visual>
      <origin
        xyz="0 0 0"
        rpy="0 0 0" />
      <geometry>
        <mesh
          filename="../meshes/right_arm_link3.STL" />
      </geometry>
      <material
        name="">
        <color
          rgba="0.686274509803922 0.658823529411765 0.63921568627451 1" />
      </material>
    </visual>
    <collision>
      <origin
        xyz="0 0 0"
        rpy="0 0 0" />
      <geometry>
        <mesh
          filename="../meshes/right_arm_link3.STL" />
      </geometry>
    </collision>
  </link>
  <joint
    name="right_arm_yaw"
    type="revolute">
    <origin
      xyz="-0.000727629925561912 -0.144902578605735 -0.016511684680204"
      rpy="0 0 0" />
    <parent
      link="right_arm_link2" />
    <child
      link="right_arm_link3" />
    <axis
      xyz="-0.00540008438890725 -0.999967746130961 -0.00594523223755775" />
    <limit
      lower="-3.14"
      upper="3.14"
      effort="35"
      velocity="3.93" />
  </joint>
  <link
    name="right_arm_link4">
    <inertial>
      <origin
        xyz="0.0140441660767094 -0.185494517170624 0.00259639757213831"
        rpy="0 0 0" />
      <mass
        value="0.244437335453167" />
      <inertia
        ixx="0.00431589752329334"
        ixy="0.00015291577337634"
        ixz="-2.1287155398325E-06"
        iyy="0.000187868138435379"
        iyz="6.50120749275084E-05"
        izz="0.00432753720574792" />
    </inertial>
    <visual>
      <origin
        xyz="0 0 0"
        rpy="0 0 0" />
      <geometry>
        <mesh
          filename="../meshes/right_arm_link4.STL" />
      </geometry>
      <material
        name="">
        <color
          rgba="0.796078431372549 0.823529411764706 0.937254901960784 1" />
      </material>
    </visual>
    <collision>
      <origin
        xyz="0 0 0"
        rpy="0 0 0" />
      <geometry>
        <mesh
          filename="../meshes/right_arm_link4.STL" />
      </geometry>
    </collision>
  </link>
  <joint
    name="right_arm_forearm_pitch"
    type="revolute">
    <origin
      xyz="-0.0162805416450604 -0.100915808864681 7.88955181040274E-05"
      rpy="0 0 0" />
    <parent
      link="right_arm_link3" />
    <child
      link="right_arm_link4" />
    <axis
      xyz="0.999056070817538 -0.00513870987355491 -0.0431342210252798" />
    <limit
      lower="-1.75"
      upper="1.75"
      effort="35"
      velocity="3.93" />
  </joint>
  <link
    name="left_arm_link1">
    <inertial>
      <origin
        xyz="0.0695623241977578 -0.000314791263562764 -0.01501462678298"
        rpy="0 0 0" />
      <mass
        value="1.02141654641539" />
      <inertia
        ixx="0.000663351428271801"
        ixy="6.35471608621194E-07"
        ixz="-1.31090265814736E-05"
        iyy="0.000670306268913229"
        iyz="3.93432295742903E-06"
        izz="0.000749026751673895" />
    </inertial>
    <visual>
      <origin
        xyz="0 0 0"
        rpy="0 0 0" />
      <geometry>
        <mesh
          filename="../meshes/left_arm_link1.STL" />
      </geometry>
      <material
        name="">
        <color
          rgba="0.686274509803922 0.658823529411765 0.63921568627451 1" />
      </material>
    </visual>
    <collision>
      <origin
        xyz="0 0 0"
        rpy="0 0 0" />
      <geometry>
        <mesh
          filename="../meshes/left_arm_link1.STL" />
      </geometry>
    </collision>
  </link>
  <joint
    name="left_arm_pitch"
    type="revolute">
    <origin
      xyz="0.255998396975687 0.360999999998998 0.000905950662110966"
      rpy="0 0 0" />
    <parent
      link="body" />
    <child
      link="left_arm_link1" />
    <axis
      xyz="0.999993738186276 0 0.00353886821419794" />
    <limit
      lower="-3.14"
      upper="3.14"
      effort="35"
      velocity="3.93" />
  </joint>
  <link
    name="left_arm_link2">
    <inertial>
      <origin
        xyz="-0.000398859336070034 -0.106502134304099 -0.0116720991745395"
        rpy="0 0 0" />
      <mass
        value="1.14381556279268" />
      <inertia
        ixx="0.000864187916365017"
        ixy="-6.04025470950221E-07"
        ixz="1.23020592454729E-07"
        iyy="0.000868173985569974"
        iyz="-3.285153926045E-05"
        izz="0.000877888207476892" />
    </inertial>
    <visual>
      <origin
        xyz="0 0 0"
        rpy="0 0 0" />
      <geometry>
        <mesh
          filename="../meshes/left_arm_link2.STL" />
      </geometry>
      <material
        name="">
        <color
          rgba="0.898039215686275 0.917647058823529 0.929411764705882 1" />
      </material>
    </visual>
    <collision>
      <origin
        xyz="0 0 0"
        rpy="0 0 0" />
      <geometry>
        <mesh
          filename="../meshes/left_arm_link2.STL" />
      </geometry>
    </collision>
  </link>
  <joint
    name="left_arm_roll"
    type="revolute">
    <origin
      xyz="0.075943806269537 0.0004019711776303 0.0160137250113609"
      rpy="0 0 0" />
    <parent
      link="left_arm_link1" />
    <child
      link="left_arm_link2" />
    <axis
      xyz="-0.00353771546750723 0.0255219795509739 0.999668001453018" />
    <limit
      lower="-0.09"
      upper="3.49"
      effort="35"
      velocity="3.93" />
  </joint>
  <link
    name="left_arm_link3">
    <inertial>
      <origin
        xyz="-0.0150072325140864 -0.0901232263530057 0.0024067380577068"
        rpy="0 0 0" />
      <mass
        value="1.06927810738706" />
      <inertia
        ixx="0.000862043958457948"
        ixy="2.29627569762329E-05"
        ixz="-3.11833151300998E-06"
        iyy="0.000726865674760579"
        iyz="2.0996375715779E-06"
        izz="0.000789259254217403" />
    </inertial>
    <visual>
      <origin
        xyz="0 0 0"
        rpy="0 0 0" />
      <geometry>
        <mesh
          filename="../meshes/left_arm_link3.STL" />
      </geometry>
      <material
        name="">
        <color
          rgba="0.686274509803922 0.658823529411765 0.63921568627451 1" />
      </material>
    </visual>
    <collision>
      <origin
        xyz="0 0 0"
        rpy="0 0 0" />
      <geometry>
        <mesh
          filename="../meshes/left_arm_link3.STL" />
      </geometry>
    </collision>
  </link>
  <joint
    name="left_arm_yaw"
    type="revolute">
    <origin
      xyz="-0.000596328788822209 -0.145350781029206 -0.0119464349934935"
      rpy="0 0 0" />
    <parent
      link="left_arm_link2" />
    <child
      link="left_arm_link3" />
    <axis
      xyz="-0.00449444159788049 -0.99966456606553 0.0255059865078566" />
    <limit
      lower="-3.14"
      upper="3.14"
      effort="35"
      velocity="3.93" />
  </joint>
  <link
    name="left_arm_link4">
    <inertial>
      <origin
        xyz="-0.0156904474364188 -0.185281223585371 0.00604283223265722"
        rpy="0 0 0" />
      <mass
        value="0.244445147945183" />
      <inertia
        ixx="0.00431291803574298"
        ixy="-0.000189336516245249"
        ixz="6.14580475647591E-06"
        iyy="0.000194147964091706"
        iyz="0.000132874237595996"
        izz="0.00432435540048329" />
    </inertial>
    <visual>
      <origin
        xyz="0 0 0"
        rpy="0 0 0" />
      <geometry>
        <mesh
          filename="../meshes/left_arm_link4.STL" />
      </geometry>
      <material
        name="">
        <color
          rgba="0.796078431372549 0.823529411764706 0.937254901960784 1" />
      </material>
    </visual>
    <collision>
      <origin
        xyz="0 0 0"
        rpy="0 0 0" />
      <geometry>
        <mesh
          filename="../meshes/left_arm_link4.STL" />
      </geometry>
    </collision>
  </link>
  <joint
    name="left_arm_forearm_pitch"
    type="revolute">
    <origin
      xyz="0.0152948275773637 -0.101041574930348 0.00239397672203362"
      rpy="0 0 0" />
    <parent
      link="left_arm_link3" />
    <child
      link="left_arm_link4" />
    <axis
      xyz="0.999921662481274 -0.00479063950012852 -0.011563679080003" />
    <limit
      lower="-1.75"
      upper="1.75"
      effort="35"
      velocity="3.93" />
  </joint>
</robot>